<?xml version="1.0" encoding="utf-8"?>
<!-- =================================================================================== -->
<!-- |    This document was autogenerated by xacro from /home/hanwen/catkin_ws/src/mushr/mushr_description/robots/mushr_tx2.urdf.xacro | -->
<!-- |    EDITING THIS FILE BY HAND IS NOT RECOMMENDED                                 | -->
<!-- =================================================================================== -->
<robot name="mushr_tx2">
  <material name="red">
    <color rgba="1 0 0 1"/>
  </material>
  <material name="orange">
    <color rgba="1 0.55 0 1"/>
  </material>
  <material name="yellow">
    <color rgba="1 1 0 1"/>
  </material>
  <material name="green">
    <color rgba="0 1 0 1"/>
  </material>
  <material name="blue">
    <color rgba="0 0 1 1"/>
  </material>
  <material name="purple">
    <color rgba="0.6 0.2 0.6 1"/>
  </material>
  <material name="white">
    <color rgba="1 1 1 1"/>
  </material>
  <material name="black">
    <color rgba="0 0 0 1"/>
  </material>
  <material name="gold">
    <color rgba="1 0.84 0 1"/>
  </material>
  <material name="teal">
    <color rgba="0 0.8 0.8 1"/>
  </material>
  <material name="none">
    <color rgba="0 0 0 1"/>
  </material>
  <material name="aluminum">
    <color rgba="0.5 0.5 0.5 1"/>
  </material>
  <material name="plastic">
    <color rgba="0.1 0.1 0.1 1"/>
  </material>
  <link name="base_footprint">
    <inertial>
      <origin rpy="0 0 0" xyz="0 0 0"/>
      <mass value="0.1"/>
      <inertia ixx="1" ixy="0" ixz="0" iyy="1" iyz="0" izz="1"/>
    </inertial>
  </link>
  <link name="base_link">
    <inertial>
      <origin rpy="0 0 0" xyz="0 0 0"/>
      <mass value="1.0"/>
      <inertia ixx="1" ixy="0" ixz="0" iyy="1" iyz="0" izz="1"/>
    </inertial>
    <visual>
      <origin rpy="0 0 0" xyz="0 0 0"/>
      <geometry>
        <mesh filename="package://mushr_description/meshes/base/tx2/mushr_base_tx2.dae"/>
      </geometry>
    </visual>
    <collision>
      <origin rpy="0 0 0" xyz="0 0 0"/>
      <geometry>
        <mesh filename="package://mushr_description/meshes/base/tx2/mushr_base_tx2_collision.dae"/>
      </geometry>
    </collision>
  </link>
  <link name="platform_link">
    <inertial>
      <origin rpy="0 0 0" xyz="0 0 0"/>
      <mass value="1.0"/>
      <inertia ixx="1" ixy="0" ixz="0" iyy="1" iyz="0" izz="1"/>
    </inertial>
  </link>
  <link name="insets_link">
    <inertial>
      <origin rpy="0 0 0" xyz="0 0 0"/>
      <mass value="1.0"/>
      <inertia ixx="1" ixy="0" ixz="0" iyy="1" iyz="0" izz="1"/>
    </inertial>
  </link>
  <joint name="base_footprint_to_base_link" type="fixed">
    <origin rpy="0 0 0" xyz="0 0 0.094655"/>
    <parent link="base_footprint"/>
    <child link="base_link"/>
  </joint>
  <joint name="base_link_to_platform_link" type="fixed">
    <origin rpy="0 0 0" xyz="0 0 0.0"/>
    <parent link="base_link"/>
    <child link="platform_link"/>
  </joint>
  <joint name="base_link_to_insets_link" type="fixed">
    <origin rpy="0 0 0" xyz="0 0 0.0"/>
    <parent link="base_link"/>
    <child link="insets_link"/>
  </joint>
  <link name="front_left/wheel_link">
    <inertial>
      <origin rpy="0 0 3.141592" xyz="0 0 0"/>
      <mass value="1.0"/>
      <inertia ixx="1" ixy="0" ixz="0" iyy="1" iyz="0" izz="1"/>
    </inertial>
    <visual>
      <origin rpy="0 0 3.141592" xyz="0 0 0"/>
      <geometry>
        <mesh filename="package://mushr_description/meshes/base/mushr_wheel.dae"/>
      </geometry>
    </visual>
    <collision>
      <origin rpy="0 0 0" xyz="0 0 0"/>
      <geometry>
        <mesh filename="package://mushr_description/meshes/base/mushr_wheel_collision.dae"/>
      </geometry>
    </collision>
  </link>
  <link name="front_right/wheel_link">
    <inertial>
      <origin rpy="0 0 0" xyz="0 0 0"/>
      <mass value="1.0"/>
      <inertia ixx="1" ixy="0" ixz="0" iyy="1" iyz="0" izz="1"/>
    </inertial>
    <visual>
      <origin rpy="0 0 0" xyz="0 0 0"/>
      <geometry>
        <mesh filename="package://mushr_description/meshes/base/mushr_wheel.dae"/>
      </geometry>
    </visual>
    <collision>
      <origin rpy="0 0 3.141592" xyz="0 0 0"/>
      <geometry>
        <mesh filename="package://mushr_description/meshes/base/mushr_wheel_collision.dae"/>
      </geometry>
    </collision>
  </link>
  <link name="back_left/wheel_link">
    <inertial>
      <origin rpy="0 0 3.141592" xyz="0 0 0"/>
      <mass value="1.0"/>
      <inertia ixx="1" ixy="0" ixz="0" iyy="1" iyz="0" izz="1"/>
    </inertial>
    <visual>
      <origin rpy="0 0 3.141592" xyz="0 0 0"/>
      <geometry>
        <mesh filename="package://mushr_description/meshes/base/mushr_wheel.dae"/>
      </geometry>
    </visual>
    <collision>
      <origin rpy="0 0 0" xyz="0 0 0"/>
      <geometry>
        <mesh filename="package://mushr_description/meshes/base/mushr_wheel_collision.dae"/>
      </geometry>
    </collision>
  </link>
  <link name="back_right/wheel_link">
    <inertial>
      <origin rpy="0 0 0" xyz="0 0 0"/>
      <mass value="1.0"/>
      <inertia ixx="1" ixy="0" ixz="0" iyy="1" iyz="0" izz="1"/>
    </inertial>
    <visual>
      <origin rpy="0 0 0" xyz="0 0 0"/>
      <geometry>
        <mesh filename="package://mushr_description/meshes/base/mushr_wheel.dae"/>
      </geometry>
    </visual>
    <collision>
      <origin rpy="0 0 3.141592" xyz="0 0 0"/>
      <geometry>
        <mesh filename="package://mushr_description/meshes/base/mushr_wheel_collision.dae"/>
      </geometry>
    </collision>
  </link>
  <link name="laser_link">
    <inertial>
      <origin rpy="0 0 0" xyz="0 0 0"/>
      <mass value="1.0"/>
      <inertia ixx="1" ixy="0" ixz="0" iyy="1" iyz="0" izz="1"/>
    </inertial>
    <visual>
      <origin rpy="0 0 0" xyz="0 0 0"/>
      <geometry>
        <mesh filename="package://mushr_description/meshes/sensors/mushr_ydlidar.dae"/>
      </geometry>
    </visual>
    <collision>
      <origin rpy="0 0 0" xyz="0 0 0"/>
      <geometry>
        <mesh filename="package://mushr_description/meshes/sensors/mushr_ydlidar_collision.dae"/>
      </geometry>
    </collision>
  </link>
  <!-- camera body, with origin at bottom screw mount -->
  <joint name="camera_joint" type="fixed">
    <origin rpy="0 0 0" xyz="0.10075 0.0 0.099"/>
    <parent link="base_link"/>
    <child link="camera_bottom_screw_frame"/>
  </joint>
  <link name="camera_bottom_screw_frame"/>
  <joint name="camera_link_joint" type="fixed">
    <origin rpy="0 0 0" xyz="0.0106 0.0175 0.0125"/>
    <parent link="camera_bottom_screw_frame"/>
    <child link="camera_link"/>
  </joint>
  <link name="camera_link">
    <visual>
      <!-- the mesh origin is at front plate in between the two infrared camera axes -->
      <origin rpy="1.57079632679 0 1.57079632679" xyz="0.0043 -0.0175 0"/>
      <geometry>
        <mesh filename="package://realsense2_description/meshes/d435.dae"/>
      </geometry>
    </visual>
    <collision>
      <origin rpy="0 0 0" xyz="0 -0.0175 0"/>
      <geometry>
        <box size="0.02505 0.09 0.025"/>
      </geometry>
    </collision>
    <inertial>
      <!-- The following are not reliable values, and should not be used for modeling -->
      <mass value="0.072"/>
      <origin xyz="0 0 0"/>
      <inertia ixx="0.003881243" ixy="0.0" ixz="0.0" iyy="0.000498940" iyz="0.0" izz="0.003879257"/>
    </inertial>
  </link>
  <link name="front_left/wheel_steer_link"/>
  <link name="front_right/wheel_steer_link"/>
  <joint name="front_left_wheel_steer" type="revolute">
    <axis xyz="0 0 1"/>
    <limit effort="1000.0" lower="-1.57" upper="1.57" velocity="10.0"/>
    <origin rpy="0 0 0" xyz="0.1385 0.115 -0.045855"/>
    <parent link="base_link"/>
    <child link="front_left/wheel_steer_link"/>
  </joint>
  <joint name="front_right_wheel_steer" type="revolute">
    <axis xyz="0 0 1"/>
    <limit effort="1000.0" lower="-1.57" upper="1.57" velocity="10.0"/>
    <origin rpy="0 0 0" xyz="0.1385 -0.115 -0.045855"/>
    <parent link="base_link"/>
    <child link="front_right/wheel_steer_link"/>
  </joint>
  <joint name="front_left_wheel_throttle" type="continuous">
    <axis xyz="0 1 0"/>
    <origin rpy="0 0 0" xyz="0 0 0"/>
    <parent link="front_left/wheel_steer_link"/>
    <child link="front_left/wheel_link"/>
  </joint>
  <joint name="front_right_wheel_throttle" type="continuous">
    <axis xyz="0 1 0"/>
    <origin rpy="0 0 0" xyz="0 0 0"/>
    <parent link="front_right/wheel_steer_link"/>
    <child link="front_right/wheel_link"/>
  </joint>
  <joint name="back_left_wheel_throttle" type="continuous">
    <axis xyz="0 1 0"/>
    <origin rpy="0 0 0" xyz="-0.158 0.115 -0.045855"/>
    <parent link="base_link"/>
    <child link="back_left/wheel_link"/>
  </joint>
  <joint name="back_right_wheel_throttle" type="continuous">
    <axis xyz="0 1 0"/>
    <origin rpy="0 0 0" xyz="-0.158 -0.115 -0.045855"/>
    <parent link="base_link"/>
    <child link="back_right/wheel_link"/>
  </joint>
  <joint name="base_link_to_laser_link" type="fixed">
    <origin rpy="0 0 0" xyz="-0.038975 0 0.15775"/>
    <parent link="base_link"/>
    <child link="laser_link"/>
  </joint>
</robot>
